Workbook

Sheet Hurdle Rate
B1: HURDLE RATE
B5: Hurdle Rate | C5: Celsius Beverages | D5: Celsius Eats
B6: Cost Of Equity | C6: 0.1369 | D6: 0.0952
B7: Cost Of Debt | C7: 0.0465
B8: Cost Of Capital | C8: 0.1368 | D8: 0.0855
A11: A. | B11: Cost Of Equity (Celsius Beverages) | I11: A. | J11: Cost Of Equity (Celsius Eats)
B12: Risk Free Rate | C12: 4.70% | J12: Median Beta (Peer Group Firm) | K12: 0.9
B13: Beta | C13: 1.53 | J13: Median D/E (Peer Group Firm) | K13: 43.47%
B14: ERP | C14: 5.88% | J14: Median Cash/Value (Peer Group Firm) | K14: 0.0194
J15: Tax Rate | K15: 0.25
J16: Debt (Firm Company) | K16: 0.2
J17: Equity (Firm Company) | K17: 0.8
B18: Share Price | C18: $ 24.00
B19: Number Of Shares Outstanding | C19: $ 232.80 (million) | J19: -Eliminate The Debt Effect (Peer Group Firm)
B20: Market Value Of Equity | C20: $ 5.587,20
A22: B. | B22: Cost Of Debt (Celsius Beverages)
B23: Risk Free Rate | C23: 4.70% | J23: -Eliminate The Cash Effect (Peer Group Firm)
B24: BBB Rating | C24: 1.50%
B25: Tax Rate | C25: 0.25
J27: +Adding A Debt Effect (Firm Company)
B32: Book Value Of Interest Debt | C32: $ 5.8 (Million)
B33: Interest Expense | C33: $ 200.000
B34: Maturity | C34: 4 years | J34: Equity / (Equity + Debt) | K34: 0.8
B35: Pre-tax Cost Of Debt | C35: 6.20%
I36: B. | J36: Cost Of Debt (Celsius Eats)
B37: Convert Book Value Interest To Market Value Interest | J37: Risk Free Rate | K37: 4.70%
J38: BBB Rating | K38: 1.50%
J39: Tax Rate | K39: 0.25
B41: Market Value Of Interest Debt | C41: $ 5,25
B42: Market Value Of Lease | C42: -
B43: Total Market Value Of Debt | C43: $ 5,25
A45: C. | B45: Cost Of Capital (Celsius Beverages)
B46: Cost Of Equity | C46: 13.69% | J46: Debt / (Equity + Debt) | K46: 0.2
B47: Cost Of Debt | C47: 4.65%
B48: Market Value Of Equity / E | C48: $ 5.587,20
B49: Market Value Of Debt / D | C49: $ 5,25 | I49: C. | J49: Cost Of Capital
J50: Cost Of Equity (Celsius Eats) | K50: 0.0952
J51: Cost Of Debt | K51: 4.65%
J52: Equity | K52: 0.8
J53: Debt | K53: 0.2
...

Sheet Parameters
B3: Summary Of Inputs Celsius Eats | F3: Summary Of Inputs Celsius Beverages
B4: Inflation Rates | C4: 0.03 | F4: Increased Revenues | H4: 50
B5: Gross Margin (Direct Opr Expense) | C5: 0.6 | F5: Growth Revenues /year | H5: 0.03
B6: G&A Cost | C6: 200 | F6: Operation Margin | H6: 0.1701
B7: Direct G&A Cost Of Good | C7: 50
B8: Allocated G&A In Celsius Eats | C8: 0.05
B9: Growth G&A | C9: 0.05
B10: Growth In Incremental G&A | C10: 0.1
B11: Cost Of Logistics | C11: 200
A14: FINITE LIFE
A16: A. | B16: Revenues
B17: Revenue (Celsius Eats)
B18: Year | C18: 0 | D18: 1 | E18: 2 | F18: 3 | G18: 4 | H18: 5 | I18: 6 | J18: 7 | K18: 8 | L18: 9 | M18: 10 | N18: 11 | O18: 12 | P18: 13 | Q18: 14 | R18: 15
B19: Number Of Products | C19: - | D19: - | E19: - | F19: 1 | G19: 2 | H19: 3 | I19: 4 | J19: 5 | K19: 6 | L19: 7 | M19: 8 | N19: 9 | O19: 10 | P19: 11 | Q19: 11 | R19: 11
B20: Revenue Per Product | C20: - | D20: - | E20: - | F20: 60 | G20: 61.8 | H20: 63.65 | I20: 65.56 | J20: 67.53 | K20: 69.56 | L20: 71.64 | M20: 73.79 | N20: 76.01 | O20: 78.29 | P20: 80.63 | Q20: 83.05 | R20: 85.55
B21: Total Revenues | C21: - | D21: - | E21: - | F21: =F19*F20 -> 60 | G21: =G19*G20 -> 123.6 | H21: =H19*H20 -> 190.95 | I21: =I19*I20 -> 262.24 | J21: =J19*J20 -> 337.65 | K21: =K19*K20 -> 417.36 | L21: =L19*L20 -> 501.48 | M21: =M19*M20 -> 590.32 | ... R21: =R19*R20 -> 941.05
B22: Direct Operasional (40%) | C22: - | D22: - | E22: - | F22: =F21*40% -> 24 | G22: =G21*40% -> 49.44 | H22: =H21*40% -> 76.38 | I22: =I21*40% -> 104.896 | J22: =J21*40% -> 135.06 | K22: =K21*40% -> 166.944 | L22: =L21*40% -> 200.592 | M22: =M21*40% -> 236.128 | ... R22: =R21*40% -> 376.42
B24: Revenue (Celsius Beverages)
B25: Year | C25: 0 | D25: 1 | E25: 2 | F25: 3 | G25: 4 | H25: 5 | I25: 6 | J25: 7 | K25: 8 | L25: 9 | M25: 10 | N25: 11 | O25: 12 | P25: 13 | Q25: 14 | R25: 15
B26: Number Of Products | C26: 0 | D26: 0 | E26: 0 | F26: 1 | G26: 2 | H26: 3 | I26: 4 | J26: 5 | K26: 6 | L26: 7 | M26: 8 | N26: 9 | O26: 10 | P26: 11 | Q26: 11 | R26: 11
B27: Increased Beverages Sales | C27: =H4 -> 50 | D27: =H4*(1+H5) -> 51.5 | E27: =D27*(1+H5) -> 53.045 | F27: =E27*(1+H5) -> 54.63635 | G27: =F27*(1+H5) -> 56.275441 | H27: =G27*(1+H5) -> 57.963704 | I27: =H27*(1+H5) -> 59.702615 | J27: =I27*(1+H5) -> 61.493693 | K27: =J27*(1+H5) -> 63.338504 | L27: =K27*(1+H5) -> 65.238659 | M27: =L27*(1+H5) -> 67.195819 | N27: =M27*(1+H5) -> 69.211694 | O27: =N27*(1+H5) -> 71.288044 | P27: =O27*(1+H5) -> 73.426686 | Q27: =P27*(1+H5) -> 75.629486 | R27: =Q27*(1+H5) -> 77.898371
B28: Total Revenues | C28: =C26*C27 -> 0 | D28: =D26*D27 -> 0 | E28: =E26*E27 -> 0 | F28: =F26*F27 -> 54.63635 | G28: =G26*G27 -> 112.55088 | H28: =H26*H27 -> 173.89111 | I28: =I26*I27 -> 238.81046 | J28: =J26*J27 -> 307.46847 | ... R28: =R26*R27 -> 856.88208
B29: Operation Income | C29: =C28*H6 -> 0 | D29: =D28*H6 -> 0 | E29: =E28*H6 -> 0 | F29: =F28*H6 -> 9.2936431 | G29: =G28*H6 -> 19.144905 | H29: =H28*H6 -> 29.578878 | I29: =I28*H6 -> 40.621659 | J29: =J28*H6 -> 52.300386 | K29: =K28*H6 -> 64.643277 | L29: =L28*H6 -> 77.679671 | M29: =M28*H6 -> 91.44007 | N29: =N28*H6 -> 105.95618 | O29: =O28*H6 -> 121.26096 | P29: =P28*H6 -> 137.38867 | Q29: =Q28*H6 -> 141.51033 | R29: =R28*H6 -> 145.75564
A31: B. | B31: Capital Expendetures
B32: Year | C32: 0 | D32: 1 | E32: 2 | F32: 3 | G32: 4 | H32: 5 | I32: 6 | J32: 7 | K32: 8 | L32: 9 | M32: 10 | N32: 11 | O32: 12 | P32: 13 | Q32: 14 | R32: 15
B33: Up-Front Acqusitions | C33: 250 | D33: - | E33: - | F33: - | G33: - | H33: - | I33: - | J33: - | K33: - | L33: - | M33: - | N33: - | O33: - | P33: - | Q33: - | R33: -
B34: Capital Investment in new food products | C34: - | D34: - | E34: - | F34: 100 | G34: =F34*(1+C4) -> 103 | H34: =G34*(1+C4) -> 106.09 | I34: =H34*(1+C4) -> 109.2727 | J34: =I34*(1+C4) -> 112.55088 | K34: =J34*(1+C4) -> 115.92741 | L34: =K34*(1+C4) -> 119.40523 | M34: =L34*(1+C4) -> 122.98739 | N34: =M34*(1+C4) -> 126.67701 | O34: =N34*(1+C4) -> 130.47732 | P34: - | Q34: - | R34: -
A36: C. | B36: Logistics System
B37: Year | C37: 0 | D37: 1 | E37: 2 | F37: 3 | G37: 4 | H37: 5 | I37: 6 | J37: 7 | K37: 8 | L37: 9 | M37: 10 | N37: 11 | O37: 12 | P37: 13 | Q37: 14 | R37: 15
B38: Capacity Used by Celsius Beverage | C38: 0.6 | D38: =C38*(1+C8) -> 0.63 | E38: =D38*(1+C8) -> 0.6615 | F38: =E38*(1+C8) -> 0.694575 | G38: =F38*(1+C8) -> 0.72930375 | H38: =G38*(1+C8) -> 0.76576894 | I38: =H38*(1+C8) -> 0.80405738 | J38: =I38*(1+C8) -> 0.84426025 | K38: =J38*(1+C8) -> 0.88647327 | L38: =K38*(1+C8) -> 0.93079693 | M38: =L38*(1+C8) -> 0.97733678 | N38: =M38*(1+C8) -> 1.0262036 | O38: =N38*(1+C8) -> 1.0775138 | P38: =O38*(1+C8) -> 1.1313895 | Q38: =P38*(1+C8) -> 1.187959 | R38: =Q38*(1+C8) -> 1.2473569
B39: Capacity Used by Celsius Eats | C39: - | D39: - | E39: - | F39: 0.2 | G39: =F39*1+8% -> 0.28 | H39: =G39*1+8% -> 0.36 | I39: =H39*1+8% -> 0.44 | J39: =I39*1+8% -> 0.52 | K39: =J39*1+8% -> 0.6 | L39: =K39*1+8% -> 0.68 | M39: =L39*1+8% -> 0.76 | N39: =M39*1+8% -> 0.84 | ... P39: =O39*1+8% -> 1 | Q39: 1 | R39: =Q39 -> 1
B40: Expansion Investment | C40: - | D40: - | E40: - | F40: - | G40: 225.1 | H40: - | I40: - | J40: - | K40: - | L40: - | M40: - | N40: 276.85 | O40: - | P40: - | Q40: - | R40: -
B41: Depreciation On Expansion (10 years) | C41: - | D41: - | E41: - | F41: - | G41: - | H41: =G40/10 -> 22.51 | I41: =H41 -> 22.51 | J41: =I41 -> 22.51 | K41: =J41 -> 22.51 | L41: =K41 -> 22.51 | M41: =L41 -> 22.51 | N41: =M41 -> 22.51 | O41: -5.17 | P41: -5.17 | Q41: -5.17 | R41: -
B43: Depreciation
B44: Year | C44: 0 | D44: 1 | E44: 2 | F44: 3 | G44: 4 | H44: 5 | I44: 6 | J44: 7 | K44: 8 | L44: 9 | M44: 10 | N44: 11 | O44: 12 | P44: 13 | Q44: 14 | R44: 15
B45: Initial Investment | C45: - | D45: - | E45: - | F45: =C100/10 -> 25 | G45: 25 | H45: 25 | I45: 25 | J45: 25 | K45: 25 | L45: 25 | M45: 25 | N45: 25 | O45: 25 | P45: - | Q45: - | R45: -
B46: Dep. Invest. New Food Products (year 3) | C46: - | D46: - | E46: - | F46: - | G46: =F101/10 -> 10 | H46: 10 | I46: 10 | J46: 10 | K46: 10 | L46: 10 | M46: 10 | N46: 10 | O46: 10 | P46: 10 | Q46: - | R46: -
B47: Dep. Invest. New Food Products (year 4) | C47: - | D47: - | E47: - | F47: - | G47: - | H47: =G101/10 -> 10.3 | I47: 10.3 | J47: 10.3 | K47: 10.3 | L47: 10.3 | M47: 10.3 | N47: 10.3 | O47: 10.3 | P47: 10.3 | Q47: 10.3 | R47: -
B48: Dep. Invest. New Food Products (year 5) | C48: - | D48: - | E48: - | F48: - | G48: - | H48: - | I48: =H101/10 -> 10.609 | J48: 10.61 | K48: 10.61 | L48: 10.61 | M48: 10.61 | N48: 10.61 | O48: 10.61 | P48: 10.61 | Q48: 10.61 | R48: 10.61
B49: Dep. Invest. New Food Products (year 6) | C49: - | D49: - | E49: - | F49: - | G49: - | H49: - | I49: - | J49: =I101/10 -> 10.92727 | K49: 10.93 | L49: 10.93 | M49: 10.93 | N49: 10.93 | O49: 10.93 | P49: 10.93 | Q49: 10.93 | R49: 10.93
...

Sheet Finite Life
B1: FINITE LIFE
A4: A. | B4: Cash Flow To The Firm
B5: Tax Rate | C5: 0.25
B7: Year | C7: 0 | D7: 1 | E7: 2 | F7: 3 | G7: 4 | H7: 5 | I7: 6 | J7: 7 | K7: 8 | L7: 9 | M7: 10 | N7: 11 | O7: 12 | P7: 13 | Q7: 14 | R7: 15
B8: Number Of Products | C8: 0 | D8: 0 | E8: 0 | F8: {=Parameters!F19:R19} -> 1 | G8: 2 | H8: 3 | I8: 4 | J8: 5 | K8: 6 | L8: 7 | M8: 8 | N8: 9 | O8: 10 | P8: 11 | Q8: 11 | R8: 11
B9: Revenues Per Product | C9: 0 | D9: 0 | E9: 0 | F9: {=Parameters!F20:R20} -> 60 | G9: 61.8 | H9: 63.65 | I9: 65.56 | J9: 67.53 | K9: 69.56 | L9: 71.64 | M9: 73.79 | N9: 76.01 | O9: 78.29 | P9: 80.63 | Q9: 83.05 | R9: 85.55
B11: Revenues | C11: 0 | D11: 0 | E11: 0 | F11: {=Parameters!F21:R21} -> 60 | G11: 123.6 | H11: 190.95 | I11: 262.24 | J11: 337.65 | K11: 417.36 | L11: 501.48 | M11: 590.32 | N11: 684.09 | O11: 782.9 | P11: 886.93 | Q11: 913.55 | R11: 941.05
B12: - Direct Oper. Exp. | C12: 0 | D12: 0 | E12: 0 | F12: {=Parameters!F22:R22} -> 24 | G12: 49.44 | H12: 76.38 | I12: 104.896 | J12: 135.06 | K12: 166.944 | L12: 200.592 | M12: 236.128 | N12: 273.636 | O12: 313.16 | P12: 354.772 | Q12: 365.42 | R12: 376.42
B13: - Depreciation | C13: 0 | D13: 0 | E13: 0 | F13: {=Parameters!F58:R58} -> 25 | G13: 35 | H13: 67.81 | I13: 78.419 | J13: 89.34727 | K13: 100.60509 | L13: 112.20274 | M13: 124.14052 | N13: 136.43874 | O13: 121.4277 | P13: 109.47773 | Q13: 99.48 | R13: 89.18
B14: - Allocated & Incerm. G&A | C14: 0 | D14: 0 | E14: 0 | F14: {=Parameters!F75:R75} -> 61.57625 | G14: 67.155063 | H14: 73.262816 | I14: 79.950956 | J14: 87.276004 | K14: 95.300054 | L14: 104.09133 | M14: 113.7248 | N14: 124.28283 | O14: 135.85595 | P14: 148.54361 | Q14: 153.37705 | R14: 158.37435
B15: - Advertising Exp | C15: 0 | D15: 0 | E15: 0 | F15: {=Parameters!F81:R81} -> 24.586357 | G15: 25.323948 | H15: 26.083667 | I15: 26.866177 | J15: 27.672162 | K15: 28.502327 | L15: 29.357397 | M15: 30.238119 | N15: 31.145262 | O15: 32.07962 | P15: 33.042009 | Q15: 34.033269 | R15: 35.054267
B16: EBIT | C16: 0 | D16: 0 | E16: 0 | F16: =SUM(F11-F12-F13-F14-F15) -> -75.162607 | G16: =SUM(G11-G12-G13-G14-G15) -> -53.319011 | H16: =SUM(H11-H12-H13-H14-H15) -> -52.586482 | I16: =SUM(I11-I12-I13-I14-I15) -> -27.892133 | J16: =SUM(J11-J12-J13-J14-J15) -> -1.7054362 | K16: =SUM(K11-K12-K13-K14-K15) -> 26.008531 | L16: =SUM(L11-L12-L13-L14-L15) -> 55.23653 | M16: =SUM(M11-M12-M13-M14-M15) -> 86.088557 | ... R16: =SUM(R11-R12-R13-R14-R15) -> 282.02138
B17: Taxes | C17: 0 | D17: 0 | E17: 0 | F17: =F16*C5 -> -18.790652 | G17: =G16*C5 -> -13.329753 | H17: =H16*C5 -> -13.146621 | I17: =I16*C5 -> -6.9730333 | J17: =J16*C5 -> -0.42635905 | K17: =K16*C5 -> 6.5021327 | L17: =L16*C5 -> 13.809133 | M17: =M16*C5 -> 21.522139 | N17: =N16*C5 -> 29.646791 | O17: =O16*C5 -> 45.094183 | P17: =P16*C5 -> 60.273661 | Q17: =Q16*C5 -> 65.30992 | R17: =R16*C5 -> 70.505346
B18: EBIT (1-t) | C18: 0 | D18: 0 | E18: 0 | F18: =F16-F17 -> -56.371956 | G18: =G16-G17 -> -39.989258 | H18: =H16-H17 -> -39.439862 | I18: =I16-I17 -> -20.9191 | J18: =J16-J17 -> -1.2790771 | K18: =K16-K17 -> 19.506398 | L18: =L16-L17 -> 41.427398 | M18: =M16-M17 -> 64.566418 | ... R18: =R16-R17 -> 211.51604
B19: + Depreciation | C19: 0 | D19: 0 | E19: 0 | F19: {=Parameters!F58:R58} -> 25 | G19: 35 | H19: 67.81 | I19: 78.419 | J19: 89.34727 | K19: 100.60509 | L19: 112.20274 | M19: 124.14052 | N19: 136.43874 | O19: 121.4277 | P19: 109.47773 | Q19: 99.48 | R19: 89.18
B20: + Fixed Allocated Exp (1-t) | C20: 0 | D20: 0 | E20: 0 | F20: =SUM(Parameters!F75-Parameters!F74)*(1-'Finite Life'!C5) -> 8.6821875 | G20: =SUM(Parameters!G75-Parameters!G74)*(1-'Finite Life'!C5) -> 9.1162969 | H20: =SUM(Parameters!H75-Parameters!H74)*(1-'Finite Life'!C5) -> 9.5721117 | I20: =SUM(Parameters!I75-Parameters!I74)*(1-'Finite Life'!C5) -> 10.050717 | J20: =SUM(Parameters!J75-Parameters!J74)*(1-'Finite Life'!C5) -> 10.553253 | K20: =SUM(Parameters!K75-Parameters!K74)*(1-'Finite Life'!C5) -> 11.080916 | L20: =SUM(Parameters!L75-Parameters!L74)*(1-'Finite Life'!C5) -> 11.634962 | M20: =SUM(Parameters!M75-Parameters!M74)*(1-'Finite Life'!C5) -> 12.21671 | N20: =SUM(Parameters!N75-Parameters!N74)*(1-'Finite Life'!C5) -> 12.827545 | O20: =SUM(Parameters!O75-Parameters!O74)*(1-'Finite Life'!C5) -> 13.468922 | P20: =SUM(Parameters!P75-Parameters!P74)*(1-'Finite Life'!C5) -> 14.142369 | Q20: =SUM(Parameters!Q75-Parameters!Q74)*(1-'Finite Life'!C5) -> 14.849487 | R20: =SUM(Parameters!R75-Parameters!R74)*(1-'Finite Life'!C5) -> 15.591961
B21: - Cap Ex | C21: 250 | D21: 0 | E21: 0 | F21: =Parameters!F34 -> 100 | G21: =Parameters!G34 -> 103 | H21: {=Parameters!H34:O34} -> 106.09 | I21: 109.2727 | J21: 112.55088 | K21: 115.92741 | L21: 119.40523 | M21: 122.98739 | N21: 126.67701 | O21: 130.47732 | P21: 0 | Q21: 0 | R21: 0
B22: - Opp. Cost Of Logistics System | C22: 0 | D22: 0 | E22: 0 | F22: 0 | G22: =Parameters!G40 -> 225.1 | H22: 0 | I22: 0 | J22: 0 | K22: 0 | L22: 0 | M22: 0 | N22: =Parameters!N40 -> 276.85 | O22: 0 | P22: 0 | Q22: 0 | R22: 0
B23: - Change In Working Capital | C23: 0 | D23: 0 | E23: -7.2 | F23: {=Parameters!F68:Q68} -> 7.632 | G23: 8.082 | H23: 8.5548 | I23: 9.0492 | J23: 9.5652 | K23: 10.0944 | L23: 10.6608 | M23: 11.2524 | N23: 11.8572 | O23: 12.4836 | P23: 3.1944 | Q23: 3.3 | R23: 0
B24: + Salvage Value | C24: 0 | D24: 0 | E24: 0 | F24: 0 | G24: 0 | H24: 0 | I24: 0 | J24: 0 | K24: 0 | L24: 0 | M24: 0 | N24: 0 | O24: 0 | P24: 0 | Q24: 0 | R24: =Parameters!C86 -> 457.676
B25: Cash Flow To The Firm | C25: -250 | D25: 0 | E25: =SUM(E19:E24) -> -7.2 | F25: =SUM(F18+F19+F20-F21-F23) -> -130.32177 | G25: =SUM(G18+G19+G20-G21-G22-G23) -> -332.05496 | H25: =SUM(H18+H19+H20-H21-H23) -> -76.70255 | I25: =SUM(I18+I19+I20-I21-I23) -> -50.771283 | J25: =SUM(J18+J19+J20-J21-J23) -> -23.494635 | K25: =SUM(K18+K19+K20-K21-K23) -> 5.1705945 | L25: =SUM(L18+L19+L20-L21-L23) -> 35.199071 | M25: =SUM(M18+M19+M20-M21-M23) -> 66.683864 | N25: =SUM(N18+N19+N20-N21+N22-N23) -> 376.52245 | O25: =SUM(O18+O19+O20-O21-O23) -> 127.21825 | P25: =SUM(P18+P19+P20-P23) -> 301.24668 | Q25: =SUM(Q18+Q19+Q20-Q23) -> 306.95925 | R25: =SUM(R18+R19+R20+R24) -> 773.964
A27: B. | B27: Celsius Eats (NPV & IRR)
B29: Cost Of Capital | C29: ='Hurdle Rate'!D8 -> 0.0855
B35: Year | C35: 0 | D35: 1 | E35: 2 | F35: 3 | G35: 4 | H35: 5 | I35: 6 | J35: 7 | K35: 8 | L35: 9 | M35: 10 | N35: 11 | O35: 12 | P35: 13 | Q35: 14 | R35: 15
B36: Incremental Cash Flow | C36: {=C25:R25} -> -250 | D36: 0 | E36: -7.2 | F36: -130.32177 | G36: -332.05496 | H36: -76.70255 | I36: -50.771283 | J36: -23.494635 | K36: 5.1705945 | L36: 35.199071 | M36: 66.683864 | N36: 376.52245 | O36: 127.21825 | P36: 301.24668 | Q36: 306.95925 | R36: 773.964
B37: Cumulated Cost Of Capital | C37: =(1+C29)^0 -> 1 | D37: =(1+C29)^1 -> 1.0855 | E37: =(1+C29)^2 -> 1.1783102 | F37: =(1+C29)^3 -> 1.2790558 | G37: =(1+C29)^4 -> 1.388415 | H37: =(1+C29)^5 -> 1.5071245 | I37: =(1+C29)^6 -> 1.6359837 | J37: =(1+C29)^7 -> 1.7758603 | K37: =(1+C29)^8 -> 1.9276963 | L37: =(1+C29)^9 -> 2.0925144 | M37: =(1+C29)^10 -> 2.2714244 | N37: =(1+C29)^11 -> 2.4656311 | O37: =(1+C29)^12 -> 2.6764426 | P37: =(1+C29)^13 -> 2.9052784 | Q37: =(1+C29)^14 -> 3.1536797 | R37: =(1+C29)^15 -> 3.4233194
B38: PV Of Cash Flows | C38: =C36/C37 -> -250 | D38: =D36/D37 -> 0 | E38: =E36/E37 -> -6.110445 | F38: =F36/F37 -> -101.88904 | G38: =G36/G37 -> -239.16117 | H38: =H36/H37 -> -50.893306 | I38: =I36/I37 -> -31.034101 | J38: =J36/J37 -> -13.230002 | ... R38: =R36/R37 -> 226.08583
B40: NPV | C40: =SUM(C38:R38) -> -16.106763
B42: IRR | C42: =IRR(C36:R36) -> 0.083052523
A44: C. | B44: Celsius Beverages
B46: Cost Of Capital | C46: ='Hurdle Rate'!C8 -> 0.1368
B52: Year | C52: 0 | D52: 1 | E52: 2 | F52: 3 | G52: 4 | H52: 5 | I52: 6 | J52: 7 | K52: 8 | L52: 9 | M52: 10 | N52: 11 | O52: 12 | P52: 13 | Q52: 14 | R52: 15
B53: Number Of Products | C53: {=Parameters!C26:R26} -> 0 | D53: 0 | E53: 0 | F53: 1 | G53: 2 | H53: 3 | I53: 4 | J53: 5 | K53: 6 | L53: 7 | M53: 8 | N53: 9 | O53: 10 | P53: 11 | Q53: 11 | R53: 11
B54: Increased Beverage Sales | C54: {=Parameters!C27:R27} -> 50 | D54: 51.5 | E54: 53.045 | F54: 54.63635 | G54: 56.275441 | H54: 57.963704 | I54: 59.702615 | J54: 61.493693 | K54: 63.338504 | L54: 65.238659 | M54: 67.195819 | N54: 69.211694 | O54: 71.288044 | P54: 73.426686 | Q54: 75.629486 | R54: 77.898371
B55: Incremental Reveneu | C55: {=Parameters!C28:R28} -> 0 | D55: 0 | E55: 0 | F55: 54.63635 | G55: 112.55088 | H55: 173.89111 | I55: 238.81046 | J55: 307.46847 | K55: 380.03102 | L55: 456.67061 | M55: 537.56655 | N55: 622.90524 | O55: 712.88044 | P55: 807.69354 | Q55: 831.92435 | R55: 856.88208
B56: Operation Income | C56: {=Parameters!C29:R29} -> 0 | D56: 0 | E56: 0 | F56: 9.2936431 | G56: 19.144905 | H56: 29.578878 | I56: 40.621659 | J56: 52.300386 | K56: 64.643277 | L56: 77.679671 | M56: 91.44007 | N56: 105.95618 | O56: 121.26096 | P56: 137.38867 | Q56: 141.51033 | R56: 145.75564
B57: Operation Income After-Tax (1-t) | C57: =C56*(1-C5) -> 0 | D57: =D56*(1-C5) -> 0 | E57: =E56*(1-C5) -> 0 | F57: =F56*(1-C5) -> 6.9702324 | G57: =G56*(1-C5) -> 14.358679 | H57: =H56*(1-C5) -> 22.184159 | I57: =I56*(1-C5) -> 30.466244 | J57: =J56*(1-C5) -> 39.22529 | K57: =K56*(1-C5) -> 48.482458 | L57: =L56*(1-C5) -> 58.259754 | M57: =M56*(1-C5) -> 68.580053 | N57: =N56*(1-C5) -> 79.467136 | O57: =O56*(1-C5) -> 90.945723 | P57: =P56*(1-C5) -> 103.0415 | Q57: =Q56*(1-C5) -> 106.13275 | R57: =R56*(1-C5) -> 109.31673
B58: Net Operation income | C58: {=C57:R57} -> 0 | D58: 0 | E58: 0 | F58: 6.9702324 | G58: 14.358679 | H58: 22.184159 | I58: 30.466244 | J58: 39.22529 | K58: 48.482458 | L58: 58.259754 | M58: 68.580053 | N58: 79.467136 | O58: 90.945723 | P58: 103.0415 | Q58: 106.13275 | R58: 109.31673
B59: PV Of Cash Flow | C59: =C58/(1+C46)^0 -> 0 | D59: =D58/(1+C46)^1 -> 0 | E59: =E58/(1+C46)^2 -> 0 | F59: =F58/(1+C46)^3 -> 4.7445504 | G59: =G58/(1+C46)^4 -> 8.5976194 | H59: =H58/(1+C46)^5 -> 11.684836 | I59: =I58/(1+C46)^6 -> 14.116094 | J59: =J58/(1+C46)^7 -> 15.987395 | K59: =K58/(1+C46)^8 -> 17.382495 | L59: =L58/(1+C46)^9 -> 18.374353 | M59: =M58/(1+C46)^10 -> 19.026424 | N59: =N58/(1+C46)^11 -> 19.393797 | O59: =O58/(1+C46)^12 -> 19.524211 | P59: =P58/(1+C46)^13 -> 19.458947 | Q59: =Q58/(1+C46)^14 -> 17.63082 | R59: =R58/(1+C46)^15 -> 15.974441
B61: Value Of Side Effects | C61: =SUM(C59:R59) -> 201.89598
...

Sheet Infinite Life
B1: INFINITE LIFE
A3: A. | B3: Cash Flow To The Firm
B4: Tax Rate | C4: 0.25
B5: Cost Of Capital | C5: ='Hurdle Rate'!D8 -> 0.0855
B6: Inflation Rates | C6: =Parameters!C4 -> 0.03
B9: Year | C9: 0 | D9: 1 | E9: 2 | F9: 3 | G9: 4 | H9: 5 | I9: 6 | J9: 7 | K9: 8 | L9: 9 | M9: 10 | N9: 11 | O9: 12 | P9: 13 | Q9: 14 | R9: 15 | S9: 16
B10: Number Of Products | C10: 0 | D10: 0 | E10: 0 | F10: {=Parameters!F93:S93} -> 1 | G10: 2 | H10: 3 | I10: 4 | J10: 5 | K10: 6 | L10: 7 | M10: 8 | N10: 9 | O10: 10 | P10: 11 | Q10: 11 | R10: 11 | S10: 11
B11: Revenues Per Product | C11: 0 | D11: 0 | E11: 0 | F11: {=Parameters!F94:S94} -> 60 | G11: 61.8 | H11: 63.65 | I11: 65.56 | J11: 67.53 | K11: 69.56 | L11: 71.64 | M11: 73.79 | N11: 76.01 | O11: 78.29 | P11: 80.63 | Q11: 83.05 | R11: 85.55 | S11: 88.1165
B13: Revenues | C13: 0 | D13: 0 | E13: 0 | F13: {=Parameters!F95:S95} -> 60 | G13: 123.6 | H13: 190.95 | I13: 262.24 | J13: 337.65 | K13: 417.36 | L13: 501.48 | M13: 590.32 | N13: 684.09 | O13: 782.9 | P13: 886.93 | Q13: 913.55 | R13: 941.05 | S13: 969.2815
B14: - Direct Oper. Exp. | C14: 0 | D14: 0 | E14: 0 | F14: {=Parameters!F96:S96} -> 24 | G14: 49.44 | H14: 76.38 | I14: 104.896 | J14: 135.06 | K14: 166.944 | L14: 200.592 | M14: 236.128 | N14: 273.636 | O14: 313.16 | P14: 354.772 | Q14: 365.42 | R14: 376.42 | S14: 387.7126
B15: - Depreciation | C15: 0 | D15: 0 | E15: 0 | F15: {=Parameters!F125:S125} -> 25 | G15: 35 | H15: 67.81 | I15: 78.419 | J15: 89.34727 | K15: 100.60509 | L15: 112.20274 | M15: 124.14052 | N15: 136.43874 | O15: 121.4277 | P15: 109.47773 | Q15: 99.48 | R15: 89.18 | S15: 91.8554
B16: - Dep. Capital Maintenance | C16: 0 | D16: 0 | E16: 0 | F16: 0 | G16: {=Parameters!G128:R128} -> 2.7318175 | H16: 6.3979166 | I16: 13.619162 | J16: 21.620885 | K16: 30.447384 | L16: 40.146997 | M16: 50.77221 | N16: 62.378437 | O16: 75.026906 | P16: 84.836902 | Q16: 92.430386 | R16: 98.23459 | S16: =R16*(1+Parameters!C4) -> 101.18163
B17: - Allocated & Incerm. G&A | C17: 0 | D17: 0 | E17: 0 | F17: {=Parameters!F144:S144} -> 61.57625 | G17: 67.155063 | H17: 73.262816 | I17: 79.950956 | J17: 87.276004 | K17: 95.300054 | L17: 104.09133 | M17: 113.7248 | N17: 124.28283 | O17: 135.85595 | P17: 148.54361 | Q17: 153.37705 | R17: 158.37435 | S17: 163.54137
B18: - Advertising Exp | C18: 0 | D18: 0 | E18: 0 | F18: {=Parameters!F150:S150} -> 24.586357 | G18: 25.323948 | H18: 26.083667 | I18: 26.866177 | J18: 27.672162 | K18: 28.502327 | L18: 29.357397 | M18: 30.238119 | N18: 31.145262 | O18: 32.07962 | P18: 33.042009 | Q18: 34.033269 | R18: 35.054267 | S18: 36.105895
B19: EBIT | C19: 0 | D19: 0 | E19: 0 | F19: =F13-F14-F15-F17-F18 -> -75.162607 | G19: =G13-G14-G15-G16-G17-G18 -> -56.050828 | H19: =H13-H14-H15-H16-H17-H18 -> -58.984399 | I19: =I13-I14-I15-I16-I17-I18 -> -41.511296 | J19: =J13-J14-J15-J16-J17-J18 -> -23.326321 | K19: =K13-K14-K15-K16-K17-K18 -> -4.438853 | L19: =L13-L14-L15-L16-L17-L18 -> 15.089534 | M19: =M13-M14-M15-M16-M17-M18 -> 35.316347 | N19: =N13-N14-N15-N16-N17-N18 -> 56.208728 | ... S19: =S13-S14-S15-S16-S17-S18 -> 188.88461
B20: Taxes | C20: 0 | D20: 0 | E20: 0 | F20: =F19*C4 -> -18.790652 | G20: =G19*C4 -> -14.012707 | H20: =H19*C4 -> -14.7461 | I20: =I19*C4 -> -10.377824 | J20: =J19*C4 -> -5.8315803 | K20: =K19*C4 -> -1.1097132 | L20: =L19*C4 -> 3.7723834 | M20: =M19*C4 -> 8.8290868 | N20: =N19*C4 -> 14.052182 | O20: =O19*C4 -> 26.337456 | P20: =P19*C4 -> 39.064436 | Q20: =Q19*C4 -> 42.202323 | R20: =R19*C4 -> 45.946698 | S20: =S19*C4 -> 47.221153
B21: EBIT (1-t) | C21: 0 | D21: 0 | E21: 0 | F21: =F19-F20 -> -56.371956 | G21: =G19-G20 -> -42.038121 | H21: =H19-H20 -> -44.238299 | I21: =I19-I20 -> -31.133472 | J21: =J19-J20 -> -17.494741 | K21: =K19-K20 -> -3.3291397 | L21: =L19-L20 -> 11.31715 | M21: =M19-M20 -> 26.487261 | ... S21: =S19-S20 -> 141.66346
B22: + Depreciation | C22: 0 | D22: 0 | E22: 0 | F22: {=Parameters!F129:R129} -> 25 | G22: 37.731817 | H22: 74.207917 | I22: 92.038162 | J22: 110.96815 | K22: 131.05247 | L22: 152.34974 | M22: 174.91273 | N22: 198.81718 | O22: 196.45461 | P22: 194.31463 | Q22: 191.91039 | R22: 187.41459 | S22: =S15+S16 -> 193.03703
B23: + Fixed Allocated Exp (1-t) | C23: 0 | D23: 0 | E23: 0 | F23: =(Parameters!F144-Parameters!F143)*(1-'Infinite Life'!C4) -> 8.6821875 | G23: =(Parameters!G144-Parameters!G143)*(1-'Infinite Life'!C4) -> 9.1162969 | H23: =(Parameters!H144-Parameters!H143)*(1-'Infinite Life'!C4) -> 9.5721117 | I23: =(Parameters!I144-Parameters!I143)*(1-'Infinite Life'!C4) -> 10.050717 | J23: =(Parameters!J144-Parameters!J143)*(1-'Infinite Life'!C4) -> 10.553253 | K23: =(Parameters!K144-Parameters!K143)*(1-'Infinite Life'!C4) -> 11.080916 | L23: =(Parameters!L144-Parameters!L143)*(1-'Infinite Life'!C4) -> 11.634962 | M23: =(Parameters!M144-Parameters!M143)*(1-'Infinite Life'!C4) -> 12.21671 | N23: =(Parameters!N144-Parameters!N143)*(1-'Infinite Life'!C4) -> 12.827545 | O23: =(Parameters!O144-Parameters!O143)*(1-'Infinite Life'!C4) -> 13.468922 | P23: =(Parameters!P144-Parameters!P143)*(1-'Infinite Life'!C4) -> 14.142369 | Q23: =(Parameters!Q144-Parameters!Q143)*(1-'Infinite Life'!C4) -> 14.849487 | R23: =(Parameters!R144-Parameters!R143)*(1-'Infinite Life'!C4) -> 15.591961 | S23: =(Parameters!S144-Parameters!S143)*(1-'Infinite Life'!C4) -> 16.371559
B24: - Cap Ex | C24: 250 | D24: 0 | E24: 0 | F24: {=Parameters!F101:O101} -> 100 | G24: 103 | H24: 106.09 | I24: 109.2727 | J24: 112.55088 | K24: 115.92741 | L24: 119.40523 | M24: 122.98739 | N24: 126.67701 | O24: 130.47732 | P24: 0 | Q24: 0 | R24: 0 | S24: 0
B25: - Capital Maintenance | C25: 0 | D25: 0 | E25: 0 | F25: {=Parameters!F126:R126} -> 27.318175 | G25: 39.392808 | H25: 78.610375 | I25: 93.636387 | J25: 109.88587 | K25: 127.44352 | L25: 146.39913 | M25: 166.83448 | N25: 188.86312 | O25: 173.12687 | P25: 160.77174 | Q25: 150.47243 | R25: 138.93953 | S25: =S22*(1+Parameters!C4) -> 198.82814
B26: - Opp. Cost Of Logistics System | C26: 0 | D26: 0 | E26: 0 | F26: 0 | G26: =Parameters!G108 -> 225.1 | H26: 0 | I26: 0 | J26: 0 | K26: 0 | L26: 0 | M26: 0 | N26: =Parameters!N108 -> 276.85 | O26: 0 | P26: 0 | Q26: 0 | R26: 0 | S26: 0
B27: - Change In Working Capital | C27: 0 | D27: 0 | E27: {=Parameters!E137:S137} -> 7.2 | F27: 7.632 | G27: 8.082 | H27: 8.5548 | I27: 9.0492 | J27: 9.5652 | K27: 10.0944 | L27: 10.6608 | M27: 11.2524 | N27: 11.8572 | O27: 12.4836 | P27: 3.1944 | Q27: 3.3 | R27: 3.3 | S27: 3.38778
B28: + Terminal Value | C28: 0 | D28: 0 | E28: 0 | F28: 0 | G28: 0 | H28: 0 | I28: 0 | J28: 0 | K28: 0 | L28: 0 | M28: 0 | N28: 0 | O28: 0 | P28: 0 | Q28: 0 | R28: =S29/(C5-C6) -> 2682.0924 | S28: 0
B29: Cash Flow To The Firm | C29: -250 | D29: 0 | E29: -7.2 | F29: =F21+F22+F23-F24-F25-F26-F27-F28 -> -157.63994 | G29: =G21+G22+G23-G24-G25-G26-G27-G28 -> -370.76482 | H29: =H21+H22+H23-H24-H25-H26-H27-H28 -> -153.71345 | I29: =I21+I22+I23-I24-I25-I26-I27-I28 -> -141.00288 | J29: =J21+J22+J23-J24-J25-J26-J27-J28 -> -127.97529 | K29: =K21+K22+K23-K24-K25-K26-K27-K28 -> -114.66108 | L29: =L21+L22+L23-L24-L25-L26-L27-L28 -> -101.16331 | M29: =M21+M22+M23-M24-M25-M26-M27-M28 -> -87.457566 | N29: =N21+N22+N23-N24-N25+N26-N27-N28 -> 203.25394 | O29: =O21+O22+O23-O24-O25-O26-O27-O28 -> -27.151887 | P29: =P21+P22+P23-P24-P25-P26-P27-P28 -> 161.68417 | Q29: =Q21+Q22+Q23-Q24-Q25-Q26-Q27-Q28 -> 179.59442 | R29: =R21+R22+R23-R24-R25-R26-R27+R28 -> 2880.6995 | S29: =S21+S22+S23-S24-S25-S26-S27-S28 -> 148.85613
B31: Terminal Value Calculation
A41: B. | B41: Celsius Eats (NPV & IRR)
B43: Cost Of Capital | C43: ='Hurdle Rate'!D8 -> 0.0855
B49: Year | C49: 0 | D49: 1 | E49: 2 | F49: 3 | G49: 4 | H49: 5 | I49: 6 | J49: 7 | K49: 8 | L49: 9 | M49: 10 | N49: 11 | O49: 12 | P49: 13 | Q49: 14 | R49: 15
B50: Incremental Cash Flow | C50: =C29 -> -250 | D50: =D29 -> 0 | E50: =E29 -> -7.2 | F50: =F29 -> -157.63994 | G50: =G29 -> -370.76482 | H50: =H29 -> -153.71345 | I50: =I29 -> -141.00288 | J50: =J29 -> -127.97529 | ... R50: =R29 -> 2880.6995
B51: Cumulated Cost Of Capital | C51: {='Finite Life'!C37:R37} -> 1 | D51: 1.0855 | E51: 1.1783102 | F51: 1.2790558 | G51: 1.388415 | H51: 1.5071245 | I51: 1.6359837 | J51: 1.7758603 | K51: 1.9276963 | L51: 2.0925144 | M51: 2.2714244 | N51: 2.4656311 | O51: 2.6764426 | P51: 2.9052784 | Q51: 3.1536797 | R51: 3.4233194
B52: PV Of Cash Flow | C52: =C50/C51 -> -250 | D52: =D50/D51 -> 0 | E52: =E50/E51 -> -6.110445 | F52: =F50/F51 -> -123.24712 | G52: =G50/G51 -> -267.04177 | H52: =H50/H51 -> -101.9912 | I52: =I50/I51 -> -86.188439 | J52: =J50/J51 -> -72.063826 | ... R52: =R50/R51 -> 841.49306
B54: NPV | C54: =SUM(C52:R52) -> -26.589839
B56: IRR | C56: =IRR(C50:R50) -> 0.082852386
A58: C. | B58: Celsius Beverages
B60: Cost Of Capital | C60: ='Hurdle Rate'!C8 -> 0.1368
B66: Year | C66: 0 | D66: 1 | E66: 2 | F66: 3 | G66: 4 | H66: 5 | I66: 6 | J66: 7 | K66: 8 | L66: 9 | M66: 10 | N66: 11 | O66: 12 | P66: 13 | Q66: 14 | R66: 15
B67: {='Finite Life'!B53:R53} -> Number Of Products | C67: 0 | D67: 0 | E67: 0 | F67: 1 | G67: 2 | H67: 3 | I67: 4 | J67: 5 | K67: 6 | L67: 7 | M67: 8 | N67: 9 | O67: 10 | P67: 11 | Q67: 11 | R67: 11
B68: {='Finite Life'!B54:R54} -> Increased Beverage Sales | C68: 50 | D68: 51.5 | E68: 53.045 | F68: 54.63635 | G68: 56.275441 | H68: 57.963704 | I68: 59.702615 | J68: 61.493693 | K68: 63.338504 | L68: 65.238659 | M68: 67.195819 | N68: 69.211694 | O68: 71.288044 | P68: 73.426686 | Q68: 75.629486 | R68: 77.898371
B69: {='Finite Life'!B55:R55} -> Incremental Reveneu | C69: 0 | D69: 0 | E69: 0 | F69: 54.63635 | G69: 112.55088 | H69: 173.89111 | I69: 238.81046 | J69: 307.46847 | K69: 380.03102 | L69: 456.67061 | M69: 537.56655 | N69: 622.90524 | O69: 712.88044 | P69: 807.69354 | Q69: 831.92435 | R69: 856.88208
...

Sheet ROC
B1: RETURN ON CAPITAL (ROC)
B3: Year | C3: Beginning BV | D3: + Capital Expendeture | E3: - Depreciation | F3: + Working Capital | G3: Ending BV | H3: Average BV | I3: EBIT (1-t) | J3: ROC
B4: 0 | C4: 0 | D4: =Parameters!C33 -> 250 | E4: 0 | F4: 0 | G4: =SUM(C4:F4) -> 250 | H4: =(C4+G4)/2 -> 125 | I4: 0 | J4: =I4/H4 -> 0
B5: 1 | C5: =G4 -> 250 | D5: 0 | E5: 0 | F5: 0 | G5: =SUM(C5:F5) -> 250 | H5: =(C5+G5)/2 -> 250 | I5: 0 | J5: =I5/H5 -> 0
B6: 2 | C6: =G5 -> 250 | D6: 0 | E6: 0 | F6: 0 | G6: =SUM(C6:F6) -> 250 | H6: =(C6+G6)/2 -> 250 | I6: 0 | J6: =I6/H6 -> 0
B7: 3 | C7: =G6 -> 250 | D7: =Parameters!F34 -> 100 | E7: =Parameters!F58 -> 25 | F7: =Parameters!E68 -> 7.2 | G7: =SUM(C7+D7-E7+F7) -> 332.2 | H7: =(C7+G7)/2 -> 291.1 | I7: ='Finite Life'!F18 -> -56.371956 | J7: =I7/H7 -> -0.19365151
B8: 4 | C8: =G7 -> 332.2 | D8: =Parameters!G34+Parameters!G40 -> 328.1 | E8: =Parameters!G58 -> 35 | F8: =Parameters!F68 -> 7.632 | G8: =SUM(C8+D8-E8+F8) -> 632.932 | H8: =(C8+G8)/2 -> 482.566 | I8: ='Finite Life'!G18 -> -39.989258 | J8: =I8/H8 -> -0.082867956
B9: 5 | C9: =G8 -> 632.932 | D9: =Parameters!H34 -> 106.09 | E9: =Parameters!H58 -> 67.81 | F9: =Parameters!G68 -> 8.082 | G9: =SUM(C9+D9-E9+F9) -> 679.294 | H9: =(C9+G9)/2 -> 656.113 | I9: ='Finite Life'!H18 -> -39.439862 | J9: =I9/H9 -> -0.060111386
B10: 6 | C10: =G9 -> 679.294 | D10: =Parameters!I34 -> 109.2727 | E10: =Parameters!I58 -> 78.419 | F10: =Parameters!H68 -> 8.5548 | G10: =SUM(C10+D10-E10+F10) -> 718.7025 | H10: =(C10+G10)/2 -> 698.99825 | I10: ='Finite Life'!I18 -> -20.9191 | J10: =I10/H10 -> -0.029927256
B11: 7 | C11: =G10 -> 718.7025 | D11: =Parameters!J34 -> 112.55088 | E11: =Parameters!J58 -> 89.34727 | F11: =Parameters!I68 -> 9.0492 | G11: =SUM(C11+D11-E11+F11) -> 750.95531 | H11: =(C11+G11)/2 -> 734.82891 | I11: ='Finite Life'!J18 -> -1.2790771 | J11: =I11/H11 -> -0.0017406462
B12: 8 | C12: =G11 -> 750.95531 | D12: =Parameters!K34 -> 115.92741 | E12: =Parameters!K58 -> 100.60509 | F12: =Parameters!J68 -> 9.5652 | G12: =SUM(C12+D12-E12+F12) -> 775.84283 | H12: =(C12+G12)/2 -> 763.39907 | I12: ='Finite Life'!K18 -> 19.506398 | J12: =I12/H12 -> 0.025552033
B13: 9 | C13: =G12 -> 775.84283 | D13: =Parameters!L34 -> 119.40523 | E13: =Parameters!L58 -> 112.20274 | F13: =Parameters!K68 -> 10.0944 | G13: =SUM(C13+D13-E13+F13) -> 793.13972 | H13: =(C13+G13)/2 -> 784.49127 | I13: ='Finite Life'!L18 -> 41.427398 | J13: =I13/H13 -> 0.052807978
B14: 10 | C14: =G13 -> 793.13972 | D14: =Parameters!M34 -> 122.98739 | E14: =Parameters!M58 -> 124.14052 | F14: =Parameters!L68 -> 10.6608 | G14: =SUM(C14+D14-E14+F14) -> 802.64738 | H14: =(C14+G14)/2 -> 797.89355 | I14: ='Finite Life'!M18 -> 64.566418 | J14: =I14/H14 -> 0.080921093
B15: 11 | C15: =G14 -> 802.64738 | D15: =Parameters!N34-Parameters!N40 -> -150.17299 | E15: =Parameters!N58 -> 136.43874 | F15: =Parameters!M68 -> 11.2524 | G15: =SUM(C15+D15-E15+F15) -> 527.28805 | H15: =(C15+G15)/2 -> 664.96772 | I15: ='Finite Life'!N18 -> 88.940374 | J15: =I15/H15 -> 0.13375142
B16: 12 | C16: =G15 -> 527.28805 | D16: =Parameters!O34 -> 130.47732 | E16: =Parameters!O58 -> 121.4277 | F16: =Parameters!N68 -> 11.8572 | G16: =SUM(C16+D16-E16+F16) -> 548.19487 | H16: =(C16+G16)/2 -> 537.74146 | I16: ='Finite Life'!O18 -> 135.28255 | J16: =I16/H16 -> 0.25157545
B17: 13 | C17: =G16 -> 548.19487 | D17: 0 | E17: =Parameters!P58 -> 109.47773 | F17: =Parameters!O68 -> 12.4836 | G17: =SUM(C17+D17-E17+F17) -> 451.20074 | H17: =(C17+G17)/2 -> 499.6978 | I17: ='Finite Life'!P18 -> 180.82098 | J17: =I17/H17 -> 0.36186067
B18: 14 | C18: =G17 -> 451.20074 | D18: 0 | E18: =Parameters!Q58 -> 99.48 | F18: =Parameters!P68 -> 3.1944 | G18: =SUM(C18+D18-E18+F18) -> 354.91514 | H18: =(C18+G18)/2 -> 403.05794 | I18: ='Finite Life'!Q18 -> 195.92976 | J18: =I18/H18 -> 0.48610818
B19: 15 | C19: =G18 -> 354.91514 | D19: 0 | E19: =Parameters!R58 -> 89.18 | F19: =Parameters!Q68 -> 3.3 | G19: =SUM(C19+D19-E19+F19) -> 269.03514 | H19: =(C19+G19)/2 -> 311.97514 | I19: ='Finite Life'!R18 -> 211.51604 | J19: =I19/H19 -> 0.67799004
C20: AGGREGATE | G20: =SUM(G7:G19) -> 7636.3477 | H20: =SUM(H7:H19) -> 7626.8301 | I20: =SUM(I7:I19) -> 779.99066 | J20: =I20/H20 -> 0.10226931
